<! this is the same size with former one , 
just use tendon instead of rope and increase the size of fingertip>
 <mujoco model="reacher">
    <compiler angle="radian" inertiafromgeom="auto"/>
	<!-- <default>
		<joint armature="10" damping="1" limited="true"/>
		<geom contype="0" friction="1 0.1 0.1" />
	</default> -->
    <asset>
        <texture type="skybox" builtin="flat" rgb1="1 1 1" rgb2="1 1 1" width="100" height="100" />
        <material name="JointColor" rgba="0.3 0.3 0.3 1.0" reflectance="0.9" shininess="0.5"/>
        <material name="LimbColor" rgba="0.9 0.9 0.9 1.0" reflectance="0.9" shininess="0.5"/>
        <material name="WhipNodeColor" rgba="1.0 0.0 1.0 1.0" reflectance="0.9" shininess="0.5"/>
        <material name="pointMassColor" rgba="1.0 1.0 1.0 1.0" />
        <material name="RefMassColor" rgba="0.2 0.9 0.1 1.0" />
    </asset>
	<option gravity="0 0 -9.81" integrator="RK4" timestep="0.0001" jacobian="dense" collision='all'/>
    <worldbody>

        <!-- Arm -->
		<geom conaffinity="0" contype="0" fromto="0 0 0 0.03 0 0" name="root" rgba="0.9 0.4 0.6 1" size=".011" type="cylinder"/>
        <body name="body0" pos="0 0 0">
            <geom fromto="0.0 0 0 0.0 0 -0.1" name="link0" rgba="0.0 0.4 0.6 1" size=".01" 
                    type="cylinder"/>
            <!geom name='geom_shoulder' type='sphere' pos='0 0 0' material='JointColor' size='0.02' mass='0'/>
			<joint axis="1 0 0" limited="true" name="joint0" pos="0 0 0" range="-3.14 3.14" 
                    type="hinge"/>
            <inertial pos='0 0 -0.05' mass='1.595' diaginertia='0.011917 0.011937 0.001325'/>

            <body name="body1" pos="0.0 0 -0.1">
				<geom fromto="0 0 0 0 0 -0.1" name="link1" rgba="0.0 0.4 0.6 1" size=".01" 
                    type="cylinder"/>
				<joint axis="1 0 0" limited="true" name="joint1" pos="0 0 0" range="-3.14 3.14" 
                    type="hinge"/>
                <inertial pos='0 0 -0.05' mass='0.869' diaginertia='0.004765 0.004855 0.000472'/>

                <body name="body_whip_node1" euler="0 0 0" pos="0 0 -0.1">
                    <joint name="joint_whip_node1_Y" type="hinge" axis="1 0 0" pos="0 0 0" 
                        range="-3.14 3.14" springref="0" stiffness="0" damping="0" />
                    <geom type="cylinder" fromto="0 0 0 0 0 -0.05" size="0.01" mass="0" />
                    <geom name="geom_whip_node1" type="sphere" material="WhipNodeColor" pos="0 0 -0.05" 
                        size="0.01" mass="0.012" />

                    <body name="body_whip_node2" euler="0 0 0" pos="0 0 -0.05">
                        <joint name="joint_whip_node2_Y" type="hinge" axis="1 0 0" pos="0 0 0" 
                            range="-3.14 3.14" springref="0" stiffness="0" damping="0" />
                        <geom type="cylinder" fromto="0 0 0 0 0 -0.05" size="0.01" mass="0" />
                        <geom name="geom_whip_node2" type="sphere" material="WhipNodeColor" pos="0 0 -0.05" 
                            size="0.01" mass="0.012" />
                    

                        <body name="body_whip_node3" euler="0 0 0" pos="0 0 -0.05">
                            <joint name="joint_whip_node3_Y" type="hinge" axis="1 0 0" pos="0 0 0" 
                                range="-3.14 3.14" springref="0" stiffness="0" damping="0" />
                            <geom type="cylinder" fromto="0 0 0 0 0 -0.05" size="0.01" mass="0" />
                            <geom name="geom_whip_node3" type="sphere" material="WhipNodeColor" pos="0 0 -0.05" 
                                size="0.01" mass="0.012" />
                            
                            <body name="body_whip_node4" euler="0 0 0" pos="0 0 -0.05">
                                <joint name="joint_whip_node4_Y" type="hinge" axis="1 0 0" pos="0 0 0" 
                                    range="-3.14 3.14" springref="0" stiffness="0" damping="0" />
                                <geom type="cylinder" fromto="0 0 0 0 0 -0.05" size="0.01" mass="0" />
                                <geom name="geom_whip_node4" type="sphere" material="WhipNodeColor" pos="0 0 -0.05" 
                                    size="0.01" mass="0.012" />

                                <body name="body_whip_node5" euler="0 0 0" pos="0 0 -0.05">
                                    <joint name="joint_whip_node5_Y" type="hinge" axis="1 0 0" pos="0 0 0" 
                                        range="-3.14 3.14" springref="0" stiffness="0" damping="0" />
                                    <geom type="cylinder" fromto="0 0 0 0 0 -0.05" size="0.01" mass="0" />
                                    <geom name="geom_whip_node5" type="sphere" material="WhipNodeColor" pos="0 0 -0.05" 
                                        size="0.01" mass="0.012" />
                                    
                                    <body name="body_whip_node6" euler="0 0 0" pos="0 0 -0.05">
                                        <joint name="joint_whip_node6_Y" type="hinge" axis="1 0 0" pos="0 0 0" 
                                            range="-3.14 3.14" springref="0" stiffness="0" damping="0" />
                                        <geom type="cylinder" fromto="0 0 0 0 0 -0.05" size="0.01" mass="0" />
                                        <geom name="geom_whip_node6" type="sphere" material="WhipNodeColor" pos="0 0 -0.05" 
                                            size="0.01" mass="0.012" />
                                        
                                        <body name="body_whip_node7" euler="0 0 0" pos="0 0 -0.05">
                                            <joint name="joint_whip_node7_Y" type="hinge" axis="1 0 0" pos="0 0 0" 
                                                range="-3.14 3.14" springref="0" stiffness="0" damping="0" />
                                            <geom type="cylinder" fromto="0 0 0 0 0 -0.05" size="0.01" mass="0" />
                                            <geom name="geom_whip_node7" type="sphere" material="WhipNodeColor" pos="0 0 -0.05" 
                                                size="0.01" mass="0.012" />
                                            
                                            <body name="body_whip_node8" euler="0 0 0" pos="0 0 -0.05">
                                                <joint name="joint_whip_node8_Y" type="hinge" axis="1 0 0" pos="0 0 0" 
                                                    range="-3.14 3.14" springref="0" stiffness="0" damping="0" />
                                                <geom type="cylinder" fromto="0 0 0 0 0 -0.05" size="0.01" mass="0" />
                                                <geom name="geom_whip_node8" type="sphere" material="WhipNodeColor" pos="0 0 -0.05" 
                                                    size="0.01" mass="0.012" />

                                                <body name="body_whip_node9" euler="0 0 0" pos="0 0 -0.05">
                                                    <joint name="joint_whip_node9_Y" type="hinge" axis="1 0 0" pos="0 0 0" 
                                                        range="-3.14 3.14" springref="0" stiffness="0" damping="0" />
                                                    <geom type="cylinder" fromto="0 0 0 0 0 -0.05" size="0.01" mass="0" />
                                                    <geom name="geom_whip_node9" type="sphere" material="WhipNodeColor" pos="0 0 -0.05" 
                                                        size="0.01" mass="0.012" />
                                                

                                                    <body name="body_whip_node10" euler="0 0 0" pos="0 0 -0.05">
                                                        <joint name="joint_whip_node10_Y" type="hinge" axis="1 0 0" pos="0 0 0" 
                                                            range="-3.14 3.14" springref="0" stiffness="0" damping="0" />
                                                        <geom type="cylinder" fromto="0 0 0 0 0 -0.05" size="0.01" mass="0" />
                                                        <geom name="geom_whip_node10" type="sphere" material="WhipNodeColor" pos="0 0 -0.05" 
                                                            size="0.01" mass="0.012" />
                                                        
                                                        <body name="body_whip_node11" euler="0 0 0" pos="0 0 -0.05">
                                                            <joint name="joint_whip_node11_Y" type="hinge" axis="1 0 0" pos="0 0 0" 
                                                                range="-3.14 3.14" springref="0" stiffness="0" damping="0" />
                                                            <geom type="cylinder" fromto="0 0 0 0 0 -0.05" size="0.01" mass="0" />
                                                            <geom name="geom_whip_node11" type="sphere" material="WhipNodeColor" pos="0 0 -0.05" 
                                                                size="0.01" mass="0.012" />

                                                            <body name="body_whip_node12" euler="0 0 0" pos="0 0 -0.05">
                                                                <joint name="joint_whip_node12_Y" type="hinge" axis="1 0 0" pos="0 0 0" 
                                                                    range="-3.14 3.14" springref="0" stiffness="0" damping="0" />
                                                                <geom type="cylinder" fromto="0 0 0 0 0 -0.05" size="0.01" mass="0" />
                                                                <geom name="geom_whip_node12" type="sphere" material="WhipNodeColor" pos="0 0 -0.05" 
                                                                    size="0.01" mass="0.012" />
                                                                
                                                                <body name="body_whip_node13" euler="0 0 0" pos="0 0 -0.05">
                                                                    <joint name="joint_whip_node13_Y" type="hinge" axis="1 0 0" pos="0 0 0" 
                                                                        range="-3.14 3.14" springref="0" stiffness="0" damping="0" />
                                                                    <geom type="cylinder" fromto="0 0 0 0 0 -0.05" size="0.01" mass="0" />
                                                                    <geom name="geom_whip_node13" type="sphere" material="WhipNodeColor" pos="0 0 -0.05" 
                                                                        size="0.01" mass="0.012" />
                                                                    
                                                                    <body name="body_whip_node14" euler="0 0 0" pos="0 0 -0.05">
                                                                        <joint name="joint_whip_node14_Y" type="hinge" axis="1 0 0" pos="0 0 0" 
                                                                            range="-3.14 3.14" springref="0" stiffness="0" damping="0" />
                                                                        <geom type="cylinder" fromto="0 0 0 0 0 -0.05" size="0.01" mass="0" />
                                                                        <geom name="geom_whip_node14" type="sphere" material="WhipNodeColor" pos="0 0 -0.05" 
                                                                            size="0.01" mass="0.012" />

                                                                        <body name="body_whip_node15" euler="0 0 0" pos="0 0 -0.05">
                                                                            <joint name="joint_whip_node15_Y" type="hinge" axis="1 0 0" pos="0 0 0" 
                                                                                range="-3.14 3.14" springref="0" stiffness="0" damping="0" />
                                                                            <geom type="cylinder" fromto="0 0 0 0 0 -0.05" size="0.01" mass="0" />
                                                                            <geom name="geom_whip_node15" type="sphere" material="WhipNodeColor" pos="0 0 -0.05" 
                                                                                size="0.01" mass="0.012" />

                                                                            <body name="body_whip_node16" euler="0 0 0" pos="0 0 -0.05">
                                                                                <joint name="joint_whip_node16_Y" type="hinge" axis="1 0 0" pos="0 0 0" 
                                                                                    range="-3.14 3.14" springref="0" stiffness="0" damping="0" />
                                                                                <geom type="cylinder" fromto="0 0 0 0 0 -0.05" size="0.01" mass="0" />
                                                                                <geom name="geom_whip_node16" type="sphere" material="WhipNodeColor" pos="0 0 -0.05" 
                                                                                    size="0.01" mass="0.012" />
                                                                            

                                                                                <body name="body_whip_node17" euler="0 0 0" pos="0 0 -0.05">
                                                                                    <joint name="joint_whip_node17_Y" type="hinge" axis="1 0 0" pos="0 0 0" 
                                                                                        range="-3.14 3.14" springref="0" stiffness="0" damping="0" />
                                                                                    <geom type="cylinder" fromto="0 0 0 0 0 -0.05" size="0.01" mass="0" />
                                                                                    <geom name="geom_whip_node17" type="sphere" material="WhipNodeColor" pos="0 0 -0.05" 
                                                                                        size="0.01" mass="0.012" />
                                                                                    
                                                                                    <body name="body_whip_node18" euler="0 0 0" pos="0 0 -0.05">
                                                                                        <joint name="joint_whip_node18_Y" type="hinge" axis="1 0 0" pos="0 0 0" 
                                                                                            range="-3.14 3.14" springref="0" stiffness="0" damping="0" />
                                                                                        <geom type="cylinder" fromto="0 0 0 0 0 -0.05" size="0.01" mass="0" />
                                                                                        <geom name="geom_whip_node18" type="sphere" material="WhipNodeColor" pos="0 0 -0.05" 
                                                                                            size="0.01" mass="0.012" />

                                                                                        <body name="body_whip_node19" euler="0 0 0" pos="0 0 -0.05">
                                                                                            <joint name="joint_whip_node19_Y" type="hinge" axis="1 0 0" pos="0 0 0" 
                                                                                                range="-3.14 3.14" springref="0" stiffness="0" damping="0" />
                                                                                            <geom type="cylinder" fromto="0 0 0 0 0 -0.05" size="0.01" mass="0" />
                                                                                            <geom name="geom_whip_node19" type="sphere" material="WhipNodeColor" pos="0 0 -0.05" 
                                                                                                size="0.01" mass="0.012" />
                                                                                            
                                                                                            <body name="fingertip" euler="0 0 0" pos="0 0 -0.05">
                                                                                                <joint name="joint_whip_node20_Y" type="hinge" axis="1 0 0" pos="0 0 0" 
                                                                                                    range="-3.14 3.14" springref="0" stiffness="0" damping="0" />
                                                                                                <geom type="cylinder" fromto="0 0 0 0 0 -0.05" size="0.01" mass="0" />
                                                                                                <geom name="geom_whip_node20" type="sphere" material="WhipNodeColor" pos="0 0 -0.05" 
                                                                                                    size="0.01" mass="0.012" />
                                                                                                <site name='fingertip' pos='0 0 -0.05' size='0.015' rgba="0 0.9 0 1" />
                                                                                            </body>
                                                                                        </body>
                                                                                    </body>
                                                                                </body>
                                                                            </body>
                                                                        </body>
                                                                    </body>
                                                                </body>
                                                            </body>
                                                        </body>
                                                    </body>
                                                </body>
                                            </body>                               
                                        </body>
                                    </body>
                                </body>
                            </body>
                        </body>
                    </body>
                </body>
            </body>
        </body>
       <!-- <body name="fingertip" pos="0 0 -1.002" >
            <freejoint/>
            <site name="end2" pos="0 0 0.01" type="sphere" size="0.01"/>
            <geom type="box" size="0.01 0.01 0.01" rgba="0 0.9 0 1"/>
        </body> -->

        <body name="target" pos="0 1 0" euler="0 0 0">
            
            <joint armature="0" axis="0 0 1" damping="0" limited="true" name="target_z" pos="0 0 0" range="-0.2 0.2" ref="0" stiffness="0" type="slide" />
            <joint armature="0" axis="0 1 0" damping="0" limited="true" name="target_y" pos="0 0 0"  range="-0.2 0.2" ref="0" stiffness="0" type="slide" />
            <!joint armature="0" axis="0 0 0" damping="0" limited="true" name="target_x" pos="0 0 0"  range="-1 1" ref="0" stiffness="0"  type="slide"/>
            <geom conaffinity="0" contype="0" name="target" pos="0 0 0" rgba="0.9 0.4 0.6 1" size=".01" type="sphere"/>
        </body>

    </worldbody>

    <!-- <tendon>
        <spatial limited="true" range="0.59 0.6" rgba=".8 .2 .1 1" width="0.007">
            <site site="end1"/>
            <site site="end1_1"/>
        </spatial>
    </tendon>
    <tendon>
        <spatial limited="true" range="0.59 0.6" rgba=".8 .2 .1 1" width="0.007">
            <site site="end1_1"/>
            <site site="end2"/>
        </spatial>
    </tendon> -->
    
    <actuator>
		<motor ctrllimited="true" ctrlrange="-250.0 250.0" gear="1.0" name="torque_0" joint="joint0"/>
		<motor ctrllimited="true" ctrlrange="-250.0 250.0" gear="1.0" name="torque_1" joint="joint1"/>
	</actuator>
</mujoco>