<!param of robotarm: upper arm:0.33; ropeN22=0.04*(22-1)=0.84; sum length: 1.54>
<mujoco model="2D_model_w_N25">
  <compiler inertiafromgeom="auto" angle="radian" />
	<option timestep='0.0001' iterations='50' integrator='Euler' collision='all' gravity="0 0 -9.81"/>
   <asset>
     <texture type="skybox" builtin="flat" rgb1="1 1 1" rgb2="1 1 1" width="100" height="100" />
      <material name="JointColor" rgba="0.3 0.3 0.3 1.0" reflectance="0.9" shininess="0.5"/>
      <material name="LimbColor" rgba="0.9 0.9 0.9 1.0" reflectance="0.9" shininess="0.5"/>
      <material name="WhipNodeColor" rgba="1.0 0.0 1.0 1.0" reflectance="0.9" shininess="0.5"/>
      <material name="pointMassColor" rgba="1.0 1.0 1.0 1.0" />
      <material name="RefMassColor" rgba="0.2 0.9 0.1 1.0" />
   </asset>
   <size njmax="8000" nconmax="4000"/>
   <worldbody>
     <body name="camera" pos="0 0 0">
        <camera name="myCamera" pos="0.7975 -3.19 -0.4785" euler="1.5707 0 0" />
      </body>
    <!-- =============  UPPER ARM START =============== -->
		<body name='body_upper_arm' pos='0 0 0' euler='0 0 0'>
      <site name='site_upper_arm_start' pos='0 0 0' /> 
      <joint name='joint_shoulder' ref='0' type='hinge' stiffness='0' pos='0 0 0' axis='0 -1 0' />
			<inertial pos='0 0 -0.15' mass='1.595' diaginertia='0.011917 0.011937 0.001325'/>
			<geom conaffinity="0" contype="0" name='geom_shoulder' type='sphere' pos='0 0 0' material='JointColor' size='0.04' mass='0'/>
			<geom conaffinity="0" contype="0" type='cylinder' fromto='0 0 0 0 0 -0.33'     material='LimbColor'  size='0.0147' mass='0'/>
      <site name='site_upper_arm_COM' pos='0 0 -0.15' /> 
      <site name='site_upper_arm_end' pos='0 0 -0.33' /> 
    	<!-- =============  UPPER ARM  END  =============== -->

      <!-- ============ FORE ARM START =============== -->
			<body name='body_fore_arm' pos='0 0 -0.33' euler='0 0 0'>
        <site name='site_fore_arm_start' pos='0 0 0' /> 
        <joint name='joint_elbow' ref='0' type='hinge' stiffness='0' pos='0 0 0' axis='0 -1 0'/>
				<inertial pos='0 0 -0.2' mass='0.869' diaginertia='0.004765 0.004855 0.000472'/>
				<geom conaffinity="0" contype="0" name='geom_elbow'       type='sphere' pos='0 0 0'      material='JointColor' size='0.04' mass='0'/>
				<geom conaffinity="0" contype="0" type='cylinder' fromto='0 0 0 0 0 -0.37'             material='LimbColor'  size='0.0147' mass='0'/>
        <site name='site_fore_arm_COM' pos='0 0 -0.2' />
				<geom conaffinity="0" contype="0" name='geom_EE' type='sphere' pos='0 0 -0.37' material='JointColor' size='0.04' mass='0'/>
        <site name='site_whip_COM' pos='0 0 -0.37' />
        <site name='site_fore_arm_end' pos='0 0 -0.37' /> 
          <body name="CB0" pos="0 0 -0.38" euler="0 1.57 0">
            <composite type="rope" count="22 1 1" spacing="0.04" offset="0 0 0" prefix="C">
              <joint armature="0.002" kind="main" damping="0.005" frictionloss="0" stiffness="0"/>
              <geom  size=".02 0.015" rgba=".8 .2 .1 1" type="capsule" mass="0.01"/>     
            </composite>
          </body>   
            <!-- === [ N, L, M, k, b, rho ] = [25,1.800000,0.300000,0.242000,0.092000,1.000000] -->
      </body>  
      </body>
      <!geom name="geom_target" type="sphere" pos=" 2.3950  0.0000  0.0000" material="LimbColor" mass="0" size="0.03" />
      <body name="body_target" pos="1.4 0 -0.4" euler="0 0 0">
            
        <joint armature="0" axis="1 0 0" damping="0" limited="true" name="target_x" pos="0 0 0" range="-0.6 0.6" ref="0" stiffness="0" type="slide" />
        <!joint armature="0" axis="0 1 0" damping="0" limited="true" name="target_y" pos="0 0 0"  range="-0.1 0.1" ref="0" stiffness="0" type="slide" />
        <joint armature="0" axis="0 0 1" damping="0" limited="true" name="target_z" pos="0 0 0"  range="-0.6 0.6" ref="0" stiffness="0"  type="slide"/>
        <geom conaffinity="0" contype="0" name="geom_target" pos="0 0 0" material="LimbColor" size=".03" type="sphere"/>
      </body>
   </worldbody>
  <actuator>
		  <motor joint='joint_shoulder' name='motor_joint_shoulder' ctrllimited="true" ctrlrange="-100.0 100.0" gear="1.0"/>
		  <motor joint='joint_elbow'    name='motor_joint_elbow'    ctrllimited="true" ctrlrange="-100.0 100.0" gear="1.0"/>
  </actuator>
</mujoco>
